#VRML_SIM R2019a utf8
WorldInfo {
}
Viewpoint {
  orientation -0.28547320260002657 -0.9476250421129212 -0.14321951737723612 0.9738113018368493
  position -1.9504441548513372 0.749784167648775 1.4322975067284789
}
TexturedBackground {
}
TexturedBackgroundLight {
}
Floor {
}
Robot {
  translation 0 0.08 0
  rotation 1 0 0 0
  children [
    DEF GR_BODY Group {
      children [
        DEF ROBOT_BODY Shape {
          appearance PBRAppearance {
            baseColor 0.9372549019607843 0.1607843137254902 0.1607843137254902
            roughness 1
            metalness 0
          }
          geometry DEF G_BODY Box {
            size 0.25 0.07 0.1
          }
        }
        Transform {
          translation 0.11 -0.05 0
          children [
            Shape {
              appearance PBRAppearance {
                baseColor 0 0 0
                roughness 1
                metalness 0
              }
              geometry Sphere {
                radius 0.03
              }
            }
          ]
        }
      ]
    }
    DEF WHEEL_JOINT HingeJoint {
      jointParameters HingeJointParameters {
        axis 0 0 1
        anchor -0.05 0 0.06
      }
      device [
        PositionSensor {
          name "encoder1"
          resolution 0.9817
        }
        RotationalMotor {
          name "motor_right"
          maxVelocity 52.3598
        }
      ]
      endPoint DEF WHEEL_1 Solid {
        translation -0.05000008432983612 3.9089878095312815e-08 0.06000000000021257
        rotation 0.4440091992866374 0.6333310728044619 -0.6338356121023719 3.9779051475360108
        children [
          DEF SHAPE_WHEEL Shape {
            appearance PBRAppearance {
              baseColor 0 0 0
              roughness 1
              metalness 0
            }
            geometry DEF G_WHEEL Cylinder {
              height 0.02
              radius 0.075
            }
          }
        ]
        boundingObject USE G_WHEEL
        physics Physics {
        }
      }
    }
    DEF WHEEL_2_JOINT HingeJoint {
      jointParameters HingeJointParameters {
        axis 0 0 1
        anchor -0.05 0 -0.06
      }
      device [
        PositionSensor {
          name "encoder2"
          resolution 0.9817
        }
        RotationalMotor {
          name "motor_left"
          maxVelocity 52.3598
        }
      ]
      endPoint Solid {
        translation -0.050000089586875386 4.152674855206924e-08 -0.05999999999977283
        rotation 0.9977058705291914 -0.047850529319327345 -0.04788864954713782 1.5722967645287678
        children [
          USE SHAPE_WHEEL
        ]
        name "solid(1)"
        boundingObject USE SHAPE_WHEEL
        physics Physics {
        }
      }
    }
    DistanceSensor {
      translation 0.12 0 0
      name "distance_sensor"
      lookupTable [
        0 0 0
        0.03 1000 0
      ]
      type "sonar"
      aperture 0.5235
      resolution 1
    }
  ]
  boundingObject USE GR_BODY
  physics Physics {
  }
  controller "U2_EXAM_EK_ANGEL"
}
Solid {
  translation 2 0 0
  children [
    DEF G_BOX_OB Shape {
      appearance PBRAppearance {
      }
      geometry Box {
        size 0.3 0.3 0.3
      }
    }
  ]
  boundingObject USE G_BOX_OB
}
